Workbook

Sheet Parâmetros
A1: Parâmetros da campanha
A2: Células em azul são editáveis. As fórmulas da aba Apuração leem daqui.
A4: Faixa | B4: Atingimento mínimo | C4: Pontos
A5: F0 - abaixo de 80% | B5: 0 | C5: 0
A6: F1 - 80% a 99% | B6: 0.8 | C6: 1000
A7: F2 - 100% a 119% | B7: 1 | C7: 2500
A8: F3 - 120% ou mais | B8: 1.2 | C8: 4000
A10: Bônus positivação (pontos) | C10: 1500
A12: Fonte: regulamento fictício da campanha Desafio Trimestral Q3/2026 (sql/01_parametros.sql).

Sheet Apuração
A1: Apuração · Desafio Trimestral Q3/2026
A2: Colunas I–L são fórmulas do Excel; M traz o resultado do SQL; M confere as duas. Qualquer 'DIVERGE' precisa de análise.
A4: Matrícula | B4: Nome | C4: Regional | D4: Situação | E4: Meta faturamento (R$) | F4: Faturamento válido (R$) | G4: Meta positivação | H4: Clientes positivados | I4: Atingimento | J4: Pontos faturamento | K4: Pontos positivação | L4: Pontos total (Excel) | M4: Pontos total (SQL) | N4: Conferência
A5: HZ0001 | B5: Úrsula Souza | C5: Sul | D5: Elegível | E5: 10100 | F5: 7866.2 | G5: 30 | H5: 34 | I5: =IF($D5="Elegível",F5/E5,"") -> 0.77883168 | J5: =IF($D5="Elegível",INDEX(Parâmetros!$C$5:$C$8,MATCH(I5,Parâmetros!$B$5:$B$8,1)),0) -> 0 | K5: =IF(AND($D5="Elegível",H5>=G5),Parâmetros!$C$10,0) -> 1500 | L5: =J5+K5 -> 1500 | M5: 1500 | N5: =IF(L5=M5,"OK","DIVERGE") -> OK
A6: HZ0002 | B6: Yasmin Souza | C6: Centro-Oeste | D6: Inelegível - inativo | E6: 7300 | F6: 6290.7 | G6: 35 | H6: 32 | I6: =IF($D6="Elegível",F6/E6,"") | J6: =IF($D6="Elegível",INDEX(Parâmetros!$C$5:$C$8,MATCH(I6,Parâmetros!$B$5:$B$8,1)),0) -> 0 | K6: =IF(AND($D6="Elegível",H6>=G6),Parâmetros!$C$10,0) -> 0 | L6: =J6+K6 -> 0 | M6: 0 | N6: =IF(L6=M6,"OK","DIVERGE") -> OK
A7: HZ0003 | B7: Carla Santos | C7: Norte | D7: Elegível | E7: 12900 | F7: 11613.2 | G7: 45 | H7: 39 | I7: =IF($D7="Elegível",F7/E7,"") -> 0.90024806 | J7: =IF($D7="Elegível",INDEX(Parâmetros!$C$5:$C$8,MATCH(I7,Parâmetros!$B$5:$B$8,1)),0) -> 1000 | K7: =IF(AND($D7="Elegível",H7>=G7),Parâmetros!$C$10,0) -> 0 | L7: =J7+K7 -> 1000 | M7: 1000 | N7: =IF(L7=M7,"OK","DIVERGE") -> OK
A8: HZ0004 | B8: Wesley Carvalho | C8: Nordeste | D8: Elegível | E8: 12700 | F8: 13301.1 | G8: 35 | H8: 37 | I8: =IF($D8="Elegível",F8/E8,"") -> 1.0473307 | J8: =IF($D8="Elegível",INDEX(Parâmetros!$C$5:$C$8,MATCH(I8,Parâmetros!$B$5:$B$8,1)),0) -> 2500 | K8: =IF(AND($D8="Elegível",H8>=G8),Parâmetros!$C$10,0) -> 1500 | L8: =J8+K8 -> 4000 | M8: 4000 | N8: =IF(L8=M8,"OK","DIVERGE") -> OK
A9: HZ0005 | B9: Isabela Silva | C9: Nordeste | D9: Elegível | E9: 6400 | F9: 6211.6 | G9: 30 | H9: 35 | I9: =IF($D9="Elegível",F9/E9,"") -> 0.9705625 | J9: =IF($D9="Elegível",INDEX(Parâmetros!$C$5:$C$8,MATCH(I9,Parâmetros!$B$5:$B$8,1)),0) -> 1000 | K9: =IF(AND($D9="Elegível",H9>=G9),Parâmetros!$C$10,0) -> 1500 | L9: =J9+K9 -> 2500 | M9: 2500 | N9: =IF(L9=M9,"OK","DIVERGE") -> OK
A10: HZ0006 | B10: Gabriela Pereira | C10: Centro-Oeste | D10: Elegível | E10: 4900 | F10: 4292.3 | G10: 30 | H10: 31 | I10: =IF($D10="Elegível",F10/E10,"") -> 0.87597959 | J10: =IF($D10="Elegível",INDEX(Parâmetros!$C$5:$C$8,MATCH(I10,Parâmetros!$B$5:$B$8,1)),0) -> 1000 | K10: =IF(AND($D10="Elegível",H10>=G10),Parâmetros!$C$10,0) -> 1500 | L10: =J10+K10 -> 2500 | M10: 2500 | N10: =IF(L10=M10,"OK","DIVERGE") -> OK
A11: HZ0007 | B11: Lucas Nascimento | C11: Centro-Oeste | D11: Elegível | E11: 5600 | F11: 5538 | G11: 35 | H11: 34 | I11: =IF($D11="Elegível",F11/E11,"") -> 0.98892857 | J11: =IF($D11="Elegível",INDEX(Parâmetros!$C$5:$C$8,MATCH(I11,Parâmetros!$B$5:$B$8,1)),0) -> 1000 | K11: =IF(AND($D11="Elegível",H11>=G11),Parâmetros!$C$10,0) -> 0 | L11: =J11+K11 -> 1000 | M11: 1000 | N11: =IF(L11=M11,"OK","DIVERGE") -> OK
A12: HZ0008 | B12: Marina Souza | C12: Sul | D12: Elegível | E12: 3000 | F12: 2793.8 | G12: 15 | H12: 19 | I12: =IF($D12="Elegível",F12/E12,"") -> 0.93126667 | J12: =IF($D12="Elegível",INDEX(Parâmetros!$C$5:$C$8,MATCH(I12,Parâmetros!$B$5:$B$8,1)),0) -> 1000 | K12: =IF(AND($D12="Elegível",H12>=G12),Parâmetros!$C$10,0) -> 1500 | L12: =J12+K12 -> 2500 | M12: 2500 | N12: =IF(L12=M12,"OK","DIVERGE") -> OK
A13: HZ0009 | B13: Wesley Souza | C13: Sudeste | D13: Elegível | E13: 12700 | F13: 10910.4 | G13: 35 | H13: 36 | I13: =IF($D13="Elegível",F13/E13,"") -> 0.85908661 | J13: =IF($D13="Elegível",INDEX(Parâmetros!$C$5:$C$8,MATCH(I13,Parâmetros!$B$5:$B$8,1)),0) -> 1000 | K13: =IF(AND($D13="Elegível",H13>=G13),Parâmetros!$C$10,0) -> 1500 | L13: =J13+K13 -> 2500 | M13: 2500 | N13: =IF(L13=M13,"OK","DIVERGE") -> OK
A14: HZ0010 | B14: Hugo Souza | C14: Sul | D14: Elegível | E14: 13200 | F14: 12718.9 | G14: 35 | H14: 41 | I14: =IF($D14="Elegível",F14/E14,"") -> 0.96355303 | J14: =IF($D14="Elegível",INDEX(Parâmetros!$C$5:$C$8,MATCH(I14,Parâmetros!$B$5:$B$8,1)),0) -> 1000 | K14: =IF(AND($D14="Elegível",H14>=G14),Parâmetros!$C$10,0) -> 1500 | L14: =J14+K14 -> 2500 | M14: 2500 | N14: =IF(L14=M14,"OK","DIVERGE") -> OK
A15: HZ0011 | B15: Lucas Oliveira | C15: Sul | D15: Elegível | E15: 6400 | F15: 6718.5 | G15: 35 | H15: 32 | I15: =IF($D15="Elegível",F15/E15,"") -> 1.0497656 | J15: =IF($D15="Elegível",INDEX(Parâmetros!$C$5:$C$8,MATCH(I15,Parâmetros!$B$5:$B$8,1)),0) -> 2500 | K15: =IF(AND($D15="Elegível",H15>=G15),Parâmetros!$C$10,0) -> 0 | L15: =J15+K15 -> 2500 | M15: 2500 | N15: =IF(L15=M15,"OK","DIVERGE") -> OK
A16: HZ0012 | B16: Wesley Carvalho | C16: Norte | D16: Elegível | E16: 11000 | F16: 11398.2 | G16: 45 | H16: 40 | I16: =IF($D16="Elegível",F16/E16,"") -> 1.0362 | J16: =IF($D16="Elegível",INDEX(Parâmetros!$C$5:$C$8,MATCH(I16,Parâmetros!$B$5:$B$8,1)),0) -> 2500 | K16: =IF(AND($D16="Elegível",H16>=G16),Parâmetros!$C$10,0) -> 0 | L16: =J16+K16 -> 2500 | M16: 2500 | N16: =IF(L16=M16,"OK","DIVERGE") -> OK
... A31: HZ0027 | B31: Diego Pereira | C31: Sudeste | D31: Elegível | E31: 11000 | F31: 10285.8 | G31: 40 | H31: 37 | I31: =IF($D31="Elegível",F31/E31,"") -> 0.93507273 | J31: =IF($D31="Elegível",INDEX(Parâmetros!$C$5:$C$8,MATCH(I31,Parâmetros!$B$5:$B$8,1)),0) -> 1000 | K31: =IF(AND($D31="Elegível",H31>=G31),Parâmetros!$C$10,0) -> 0 | L31: =J31+K31 -> 1000 | M31: 1000 | N31: =IF(L31=M31,"OK","DIVERGE") -> OK
A32: HZ0028 | B32: Sabrina Souza | C32: Nordeste | D32: Pendente - sem meta | F32: 11211.5 | H32: 42 | I32: =IF($D32="Elegível",F32/E32,"") | J32: =IF($D32="Elegível",INDEX(Parâmetros!$C$5:$C$8,MATCH(I32,Parâmetros!$B$5:$B$8,1)),0) -> 0 | K32: =IF(AND($D32="Elegível",H32>=G32),Parâmetros!$C$10,0) -> 0 | L32: =J32+K32 -> 0 | M32: 0 | N32: =IF(L32=M32,"OK","DIVERGE") -> OK
A33: HZ0029 | B33: Rafael Oliveira | C33: Nordeste | D33: Elegível | E33: 11700 | F33: 10244.1 | G33: 30 | H33: 34 | I33: =IF($D33="Elegível",F33/E33,"") -> 0.8755641 | J33: =IF($D33="Elegível",INDEX(Parâmetros!$C$5:$C$8,MATCH(I33,Parâmetros!$B$5:$B$8,1)),0) -> 1000 | K33: =IF(AND($D33="Elegível",H33>=G33),Parâmetros!$C$10,0) -> 1500 | L33: =J33+K33 -> 2500 | M33: 2500 | N33: =IF(L33=M33,"OK","DIVERGE") -> OK
A34: HZ0030 | B34: Queila Nascimento | C34: Sudeste | D34: Elegível | E34: 9500 | F34: 9340.6 | G34: 35 | H34: 36 | I34: =IF($D34="Elegível",F34/E34,"") -> 0.98322105 | J34: =IF($D34="Elegível",INDEX(Parâmetros!$C$5:$C$8,MATCH(I34,Parâmetros!$B$5:$B$8,1)),0) -> 1000 | K34: =IF(AND($D34="Elegível",H34>=G34),Parâmetros!$C$10,0) -> 1500 | L34: =J34+K34 -> 2500 | M34: 2500 | N34: =IF(L34=M34,"OK","DIVERGE") -> OK
A35: HZ0031 | B35: Wesley Santos | C35: Nordeste | D35: Elegível | E35: 12400 | F35: 11142.8 | G35: 45 | H35: 44 | I35: =IF($D35="Elegível",F35/E35,"") -> 0.8986129 | J35: =IF($D35="Elegível",INDEX(Parâmetros!$C$5:$C$8,MATCH(I35,Parâmetros!$B$5:$B$8,1)),0) -> 1000 | K35: =IF(AND($D35="Elegível",H35>=G35),Parâmetros!$C$10,0) -> 0 | L35: =J35+K35 -> 1000 | M35: 1000 | N35: =IF(L35=M35,"OK","DIVERGE") -> OK
A36: HZ0032 | B36: Queila Rodrigues | C36: Sudeste | D36: Elegível | E36: 15500 | F36: 12354.9 | G36: 40 | H36: 40 | I36: =IF($D36="Elegível",F36/E36,"") -> 0.79709032 | J36: =IF($D36="Elegível",INDEX(Parâmetros!$C$5:$C$8,MATCH(I36,Parâmetros!$B$5:$B$8,1)),0) -> 0 | K36: =IF(AND($D36="Elegível",H36>=G36),Parâmetros!$C$10,0) -> 1500 | L36: =J36+K36 -> 1500 | M36: 1500 | N36: =IF(L36=M36,"OK","DIVERGE") -> OK
A37: HZ0033 | B37: Ana Nascimento | C37: Sudeste | D37: Inelegível - inativo | E37: 15300 | F37: 12910.2 | G37: 45 | H37: 44 | I37: =IF($D37="Elegível",F37/E37,"") | J37: =IF($D37="Elegível",INDEX(Parâmetros!$C$5:$C$8,MATCH(I37,Parâmetros!$B$5:$B$8,1)),0) -> 0 | K37: =IF(AND($D37="Elegível",H37>=G37),Parâmetros!$C$10,0) -> 0 | L37: =J37+K37 -> 0 | M37: 0 | N37: =IF(L37=M37,"OK","DIVERGE") -> OK
A38: HZ0034 | B38: Wesley Carvalho | C38: Sudeste | D38: Pendente - sem meta | F38: 8385.8 | H38: 33 | I38: =IF($D38="Elegível",F38/E38,"") | J38: =IF($D38="Elegível",INDEX(Parâmetros!$C$5:$C$8,MATCH(I38,Parâmetros!$B$5:$B$8,1)),0) -> 0 | K38: =IF(AND($D38="Elegível",H38>=G38),Parâmetros!$C$10,0) -> 0 | L38: =J38+K38 -> 0 | M38: 0 | N38: =IF(L38=M38,"OK","DIVERGE") -> OK
A39: HZ0035 | B39: Karen Souza | C39: Sudeste | D39: Elegível | E39: 3300 | F39: 3681.6 | G39: 30 | H39: 29 | I39: =IF($D39="Elegível",F39/E39,"") -> 1.1156364 | J39: =IF($D39="Elegível",INDEX(Parâmetros!$C$5:$C$8,MATCH(I39,Parâmetros!$B$5:$B$8,1)),0) -> 2500 | K39: =IF(AND($D39="Elegível",H39>=G39),Parâmetros!$C$10,0) -> 0 | L39: =J39+K39 -> 2500 | M39: 2500 | N39: =IF(L39=M39,"OK","DIVERGE") -> OK
A40: HZ0036 | B40: Gabriela Almeida | C40: Norte | D40: Elegível | E40: 10100 | F40: 10243.9 | G40: 40 | H40: 40 | I40: =IF($D40="Elegível",F40/E40,"") -> 1.0142475 | J40: =IF($D40="Elegível",INDEX(Parâmetros!$C$5:$C$8,MATCH(I40,Parâmetros!$B$5:$B$8,1)),0) -> 2500 | K40: =IF(AND($D40="Elegível",H40>=G40),Parâmetros!$C$10,0) -> 1500 | L40: =J40+K40 -> 4000 | M40: 4000 | N40: =IF(L40=M40,"OK","DIVERGE") -> OK
A41: HZ0037 | B41: Paulo Costa | C41: Centro-Oeste | D41: Elegível | E41: 3400 | F41: 2961.9 | G41: 20 | H41: 22 | I41: =IF($D41="Elegível",F41/E41,"") -> 0.87114706 | J41: =IF($D41="Elegível",INDEX(Parâmetros!$C$5:$C$8,MATCH(I41,Parâmetros!$B$5:$B$8,1)),0) -> 1000 | K41: =IF(AND($D41="Elegível",H41>=G41),Parâmetros!$C$10,0) -> 1500 | L41: =J41+K41 -> 2500 | M41: 2500 | N41: =IF(L41=M41,"OK","DIVERGE") -> OK
A42: HZ0038 | B42: Lucas Costa | C42: Nordeste | D42: Elegível | E42: 4300 | F42: 3350 | G42: 30 | H42: 25 | I42: =IF($D42="Elegível",F42/E42,"") -> 0.77906977 | J42: =IF($D42="Elegível",INDEX(Parâmetros!$C$5:$C$8,MATCH(I42,Parâmetros!$B$5:$B$8,1)),0) -> 0 | K42: =IF(AND($D42="Elegível",H42>=G42),Parâmetros!$C$10,0) -> 0 | L42: =J42+K42 -> 0 | M42: 0 | N42: =IF(L42=M42,"OK","DIVERGE") -> OK
A43: HZ0039 | B43: Úrsula Souza | C43: Nordeste | D43: Elegível | E43: 4200 | F43: 3457.6 | G43: 30 | H43: 28 | I43: =IF($D43="Elegível",F43/E43,"") -> 0.8232381 | J43: =IF($D43="Elegível",INDEX(Parâmetros!$C$5:$C$8,MATCH(I43,Parâmetros!$B$5:$B$8,1)),0) -> 1000 | K43: =IF(AND($D43="Elegível",H43>=G43),Parâmetros!$C$10,0) -> 0 | L43: =J43+K43 -> 1000 | M43: 1000 | N43: =IF(L43=M43,"OK","DIVERGE") -> OK
A44: HZ0040 | B44: Diego Santos | C44: Sudeste | D44: Elegível | E44: 10500 | F44: 9843.9 | G44: 35 | H44: 36 | I44: =IF($D44="Elegível",F44/E44,"") -> 0.93751429 | J44: =IF($D44="Elegível",INDEX(Parâmetros!$C$5:$C$8,MATCH(I44,Parâmetros!$B$5:$B$8,1)),0) -> 1000 | K44: =IF(AND($D44="Elegível",H44>=G44),Parâmetros!$C$10,0) -> 1500 | L44: =J44+K44 -> 2500 | M44: 2500 | N44: =IF(L44=M44,"OK","DIVERGE") -> OK
A45: HZ0041 | B45: Nicolas Oliveira | C45: Nordeste | D45: Elegível | E45: 11600 | F45: 9819.6 | G45: 35 | H45: 36 | I45: =IF($D45="Elegível",F45/E45,"") -> 0.84651724 | J45: =IF($D45="Elegível",INDEX(Parâmetros!$C$5:$C$8,MATCH(I45,Parâmetros!$B$5:$B$8,1)),0) -> 1000 | K45: =IF(AND($D45="Elegível",H45>=G45),Parâmetros!$C$10,0) -> 1500 | L45: =J45+K45 -> 2500 | M45: 2500 | N45: =IF(L45=M45,"OK","DIVERGE") -> OK
A46: HZ0042 | B46: Carla Rodrigues | C46: Centro-Oeste | D46: Elegível | E46: 8100 | F46: 8588.9 | G46: 40 | H46: 37 | I46: =IF($D46="Elegível",F46/E46,"") -> 1.060358 | J46: =IF($D46="Elegível",INDEX(Parâmetros!$C$5:$C$8,MATCH(I46,Parâmetros!$B$5:$B$8,1)),0) -> 2500 | K46: =IF(AND($D46="Elegível",H46>=G46),Parâmetros!$C$10,0) -> 0 | L46: =J46+K46 -> 2500 | M46: 2500 | N46: =IF(L46=M46,"OK","DIVERGE") -> OK
A47: HZ0043 | B47: Rafael Silva | C47: Sudeste | D47: Elegível | E47: 3900 | F47: 4570.9 | G47: 30 | H47: 30 | I47: =IF($D47="Elegível",F47/E47,"") -> 1.1720256 | J47: =IF($D47="Elegível",INDEX(Parâmetros!$C$5:$C$8,MATCH(I47,Parâmetros!$B$5:$B$8,1)),0) -> 2500 | K47: =IF(AND($D47="Elegível",H47>=G47),Parâmetros!$C$10,0) -> 1500 | L47: =J47+K47 -> 4000 | M47: 4000 | N47: =IF(L47=M47,"OK","DIVERGE") -> OK
A48: HZ0044 | B48: Paulo Santos | C48: Centro-Oeste | D48: Elegível | E48: 2200 | F48: 2335.1 | G48: 20 | H48: 21 | I48: =IF($D48="Elegível",F48/E48,"") -> 1.0614091 | J48: =IF($D48="Elegível",INDEX(Parâmetros!$C$5:$C$8,MATCH(I48,Parâmetros!$B$5:$B$8,1)),0) -> 2500 | K48: =IF(AND($D48="Elegível",H48>=G48),Parâmetros!$C$10,0) -> 1500 | L48: =J48+K48 -> 4000 | M48: 4000 | N48: =IF(L48=M48,"OK","DIVERGE") -> OK
A49: HZ0045 | B49: Marina Lima | C49: Sul | D49: Elegível | E49: 5800 | F49: 6610.3 | G49: 30 | H49: 34 | I49: =IF($D49="Elegível",F49/E49,"") -> 1.1397069 | J49: =IF($D49="Elegível",INDEX(Parâmetros!$C$5:$C$8,MATCH(I49,Parâmetros!$B$5:$B$8,1)),0) -> 2500 | K49: =IF(AND($D49="Elegível",H49>=G49),Parâmetros!$C$10,0) -> 1500 | L49: =J49+K49 -> 4000 | M49: 4000 | N49: =IF(L49=M49,"OK","DIVERGE") -> OK
A50: HZ0046 | B50: Yasmin Almeida | C50: Sudeste | D50: Elegível | E50: 2700 | F50: 2504 | G50: 20 | H50: 20 | I50: =IF($D50="Elegível",F50/E50,"") -> 0.92740741 | J50: =IF($D50="Elegível",INDEX(Parâmetros!$C$5:$C$8,MATCH(I50,Parâmetros!$B$5:$B$8,1)),0) -> 1000 | K50: =IF(AND($D50="Elegível",H50>=G50),Parâmetros!$C$10,0) -> 1500 | L50: =J50+K50 -> 2500 | M50: 2500 | N50: =IF(L50=M50,"OK","DIVERGE") -> OK
... A53: HZ0049 | B53: Queila Souza | C53: Centro-Oeste | D53: Elegível | E53: 6100 | F53: 7253.8 | G53: 30 | H53: 32 | I53: =IF($D53="Elegível",F53/E53,"") -> 1.1891475 | J53: =IF($D53="Elegível",INDEX(Parâmetros!$C$5:$C$8,MATCH(I53,Parâmetros!$B$5:$B$8,1)),0) -> 2500 | K53: =IF(AND($D53="Elegível",H53>=G53),Parâmetros!$C$10,0) -> 1500 | L53: =J53+K53 -> 4000 | M53: 4000 | N53: =IF(L53=M53,"OK","DIVERGE") -> OK
A54: HZ0050 | B54: Hugo Costa | C54: Norte | D54: Pendente - sem meta | F54: 2668.7 | H54: 27 | I54: =IF($D54="Elegível",F54/E54,"") | J54: =IF($D54="Elegível",INDEX(Parâmetros!$C$5:$C$8,MATCH(I54,Parâmetros!$B$5:$B$8,1)),0) -> 0 | K54: =IF(AND($D54="Elegível",H54>=G54),Parâmetros!$C$10,0) -> 0 | L54: =J54+K54 -> 0 | M54: 0 | N54: =IF(L54=M54,"OK","DIVERGE") -> OK
A55: HZ0051 | B55: Bruno Nascimento | C55: Nordeste | D55: Elegível | E55: 12800 | F55: 10538.2 | G55: 35 | H55: 35 | I55: =IF($D55="Elegível",F55/E55,"") -> 0.82329688 | J55: =IF($D55="Elegível",INDEX(Parâmetros!$C$5:$C$8,MATCH(I55,Parâmetros!$B$5:$B$8,1)),0) -> 1000 | K55: =IF(AND($D55="Elegível",H55>=G55),Parâmetros!$C$10,0) -> 1500 | L55: =J55+K55 -> 2500 | M55: 2500 | N55: =IF(L55=M55,"OK","DIVERGE") -> OK
A56: HZ0052 | B56: Isabela Santos | C56: Sudeste | D56: Elegível | E56: 4600 | F56: 4961.5 | G56: 35 | H56: 35 | I56: =IF($D56="Elegível",F56/E56,"") -> 1.078587 | J56: =IF($D56="Elegível",INDEX(Parâmetros!$C$5:$C$8,MATCH(I56,Parâmetros!$B$5:$B$8,1)),0) -> 2500 | K56: =IF(AND($D56="Elegível",H56>=G56),Parâmetros!$C$10,0) -> 1500 | L56: =J56+K56 -> 4000 | M56: 4000 | N56: =IF(L56=M56,"OK","DIVERGE") -> OK
A57: HZ0053 | B57: Vinícius Carvalho | C57: Nordeste | D57: Elegível | E57: 5000 | F57: 6137.5 | G57: 35 | H57: 30 | I57: =IF($D57="Elegível",F57/E57,"") -> 1.2275 | J57: =IF($D57="Elegível",INDEX(Parâmetros!$C$5:$C$8,MATCH(I57,Parâmetros!$B$5:$B$8,1)),0) -> 4000 | K57: =IF(AND($D57="Elegível",H57>=G57),Parâmetros!$C$10,0) -> 0 | L57: =J57+K57 -> 4000 | M57: 4000 | N57: =IF(L57=M57,"OK","DIVERGE") -> OK
...

Sheet Qualidade - resumo
A1: Regras de qualidade · ocorrências por regra
A2: Bloqueia = registro sai da apuração · Alerta = corrigido automaticamente
A3: regra | B3: severidade | C3: tabela | D3: ocorrencias
A4: DQ01 Venda duplicada | B4: Bloqueia | C4: vendas | D4: 944
A5: DQ02 Matrícula não cadastrada | B5: Bloqueia | C5: vendas | D5: 55
A6: DQ03 Venda fora do período | B6: Bloqueia | C6: vendas | D6: 70
A7: DQ04 Valor inválido | B7: Bloqueia | C7: vendas | D7: 38
A8: DQ05 Participante sem meta | B8: Bloqueia | C8: metas | D8: 6
A9: DQ06 Matrícula fora do padrão | B9: Alerta | C9: participantes | D9: 12
A10: DQ07 Resgate acima do saldo | B10: Bloqueia | C10: resgates | D10: 28

Sheet Qualidade - detalhe
A1: Ocorrências de qualidade (evidência por registro)
A3: regra | B3: severidade | C3: tabela | D3: id_registro | E3: matricula | F3: detalhe
A4: DQ01 Venda duplicada | B4: Bloqueia | C4: vendas | D4: V009056 | E4: HZ0151 | F4: Duplicata de V000017 no LOTE-05
A5: DQ01 Venda duplicada | B5: Bloqueia | C5: vendas | D5: V009057 | E5: HZ0172 | F5: Duplicata de V000030 no LOTE-05
A6: DQ01 Venda duplicada | B6: Bloqueia | C6: vendas | D6: V009058 | E6: HZ0126 | F6: Duplicata de V000073 no LOTE-05
A7: DQ01 Venda duplicada | B7: Bloqueia | C7: vendas | D7: V009059 | E7: HZ0147 | F7: Duplicata de V000092 no LOTE-05
A8: DQ01 Venda duplicada | B8: Bloqueia | C8: vendas | D8: V009060 | E8: HZ0052 | F8: Duplicata de V000112 no LOTE-05
A9: DQ01 Venda duplicada | B9: Bloqueia | C9: vendas | D9: V009061 | E9: HZ0143 | F9: Duplicata de V000118 no LOTE-05
A10: DQ01 Venda duplicada | B10: Bloqueia | C10: vendas | D10: V009062 | E10: HZ0014 | F10: Duplicata de V000119 no LOTE-05
A11: DQ01 Venda duplicada | B11: Bloqueia | C11: vendas | D11: V009063 | E11: HZ0109 | F11: Duplicata de V000161 no LOTE-05
A12: DQ01 Venda duplicada | B12: Bloqueia | C12: vendas | D12: V009064 | E12: HZ0029 | F12: Duplicata de V000173 no LOTE-05
A13: DQ01 Venda duplicada | B13: Bloqueia | C13: vendas | D13: V009065 | E13: HZ0120 | F13: Duplicata de V000175 no LOTE-05
A14: DQ01 Venda duplicada | B14: Bloqueia | C14: vendas | D14: V009066 | E14: HZ0139 | F14: Duplicata de V000183 no LOTE-05
... A1128: DQ06 Matrícula fora do padrão | B1128: Alerta | C1128: participantes | D1128: hz0145 | E1128: HZ0145 | F1128: Valor original: "hz0145" → normalizado: "HZ0145"
A1129: DQ07 Resgate acima do saldo | B1129: Bloqueia | C1129: resgates | E1129: HZ0014 | F1129: Apurado 2500 pts, resgatado 25000 pts (saldo -22500)
A1130: DQ07 Resgate acima do saldo | B1130: Bloqueia | C1130: resgates | E1130: HZ0016 | F1130: Apurado 1000 pts, resgatado 1800 pts (saldo -800)
A1131: DQ07 Resgate acima do saldo | B1131: Bloqueia | C1131: resgates | E1131: HZ0017 | F1131: Apurado 1000 pts, resgatado 1800 pts (saldo -800)
A1132: DQ07 Resgate acima do saldo | B1132: Bloqueia | C1132: resgates | E1132: HZ0027 | F1132: Apurado 1000 pts, resgatado 2800 pts (saldo -1800)
A1133: DQ07 Resgate acima do saldo | B1133: Bloqueia | C1133: resgates | E1133: HZ0030 | F1133: Apurado 2500 pts, resgatado 2800 pts (saldo -300)
A1134: DQ07 Resgate acima do saldo | B1134: Bloqueia | C1134: resgates | E1134: HZ0032 | F1134: Apurado 1500 pts, resgatado 2800 pts (saldo -1300)
A1135: DQ07 Resgate acima do saldo | B1135: Bloqueia | C1135: resgates | E1135: HZ0033 | F1135: Apurado 0 pts, resgatado 3600 pts (saldo -3600)
A1136: DQ07 Resgate acima do saldo | B1136: Bloqueia | C1136: resgates | E1136: HZ0036 | F1136: Apurado 4000 pts, resgatado 27000 pts (saldo -23000)
A1137: DQ07 Resgate acima do saldo | B1137: Bloqueia | C1137: resgates | E1137: HZ0044 | F1137: Apurado 4000 pts, resgatado 25000 pts (saldo -21000)
A1138: DQ07 Resgate acima do saldo | B1138: Bloqueia | C1138: resgates | E1138: HZ0048 | F1138: Apurado 1000 pts, resgatado 25000 pts (saldo -24000)
A1139: DQ07 Resgate acima do saldo | B1139: Bloqueia | C1139: resgates | E1139: HZ0061 | F1139: Apurado 0 pts, resgatado 1500 pts (saldo -1500)
A1140: DQ07 Resgate acima do saldo | B1140: Bloqueia | C1140: resgates | E1140: HZ0063 | F1140: Apurado 1000 pts, resgatado 2300 pts (saldo -1300)
... A1156: DQ07 Resgate acima do saldo | B1156: Bloqueia | C1156: resgates | E1156: HZ0178 | F1156: Apurado 1000 pts, resgatado 3600 pts (saldo -2600)

Sheet Impacto
A1: Participantes cuja pontuação mudaria sem o tratamento de qualidade
A2: Diferença positiva = pontos que seriam pagos indevidamente
A3: matricula | B3: nome | C3: regional | D3: pontos_sem_tratamento | E3: pontos_apurados | F3: diferenca
A4: HZ0085 | B4: Gabriela Almeida | C4: Sudeste | D4: 4000 | E4: 1000 | F4: 3000
A5: HZ0092 | B5: Diego Rodrigues | C5: Nordeste | D5: 5500 | E5: 2500 | F5: 3000
A6: HZ0129 | B6: Sabrina Pereira | C6: Norte | D6: 5500 | E6: 2500 | F6: 3000
A7: HZ0025 | B7: Diego Carvalho | C7: Norte | D7: 2500 | E7: 0 | F7: 2500
A8: HZ0005 | B8: Isabela Silva | C8: Nordeste | D8: 4000 | E8: 2500 | F8: 1500
A9: HZ0007 | B9: Lucas Nascimento | C9: Centro-Oeste | D9: 2500 | E9: 1000 | F9: 1500
A10: HZ0008 | B10: Marina Souza | C10: Sul | D10: 4000 | E10: 2500 | F10: 1500
A11: HZ0014 | B11: Úrsula Melo | C11: Sudeste | D11: 4000 | E11: 2500 | F11: 1500
A12: HZ0016 | B12: Gabriela Nascimento | C12: Sudeste | D12: 2500 | E12: 1000 | F12: 1500
A13: HZ0017 | B13: Úrsula Rodrigues | C13: Sul | D13: 2500 | E13: 1000 | F13: 1500
A14: HZ0021 | B14: Marina Costa | C14: Nordeste | D14: 4000 | E14: 2500 | F14: 1500
A15: HZ0026 | B15: Fábio Almeida | C15: Centro-Oeste | D15: 4000 | E15: 2500 | F15: 1500
... A92: HZ0172 | B92: Nicolas Silva | C92: Nordeste | D92: 1000 | E92: 0 | F92: 1000

Sheet Resgates x saldo
A1: Resgates acima do saldo apurado (bloquear antes de liberar o prêmio)
A3: matricula | B3: nome | C3: situacao | D3: pontos_apurados | E3: pontos_resgatados | F3: saldo | G3: qtd_resgates
A4: HZ0074 | B4: Ana Souza | C4: Inelegível - inativo | D4: 0 | E4: 26800 | F4: -26800 | G4: 2
A5: HZ0117 | B5: Vinícius Pereira | C5: Inelegível - inativo | D5: 0 | E5: 25000 | F5: -25000 | G5: 1
A6: HZ0048 | B6: Sabrina Rodrigues | C6: Elegível | D6: 1000 | E6: 25000 | F6: -24000 | G6: 1
A7: HZ0081 | B7: João Almeida | C7: Elegível | D7: 1000 | E7: 25000 | F7: -24000 | G7: 1
A8: HZ0036 | B8: Gabriela Almeida | C8: Elegível | D8: 4000 | E8: 27000 | F8: -23000 | G8: 3
A9: HZ0014 | B9: Úrsula Melo | C9: Elegível | D9: 2500 | E9: 25000 | F9: -22500 | G9: 1
A10: HZ0142 | B10: Olívia Lima | C10: Elegível | D10: 2500 | E10: 25000 | F10: -22500 | G10: 1
A11: HZ0044 | B11: Paulo Santos | C11: Elegível | D11: 4000 | E11: 25000 | F11: -21000 | G11: 1
A12: HZ0088 | B12: Bruno Santos | C12: Elegível | D12: 4000 | E12: 25000 | F12: -21000 | G12: 1
A13: HZ0033 | B13: Ana Nascimento | C13: Inelegível - inativo | D13: 0 | E13: 3600 | F13: -3600 | G13: 2
A14: HZ0178 | B14: Bruno Nascimento | C14: Elegível | D14: 1000 | E14: 3600 | F14: -2600 | G14: 2
A15: HZ0027 | B15: Diego Pereira | C15: Elegível | D15: 1000 | E15: 2800 | F15: -1800 | G15: 2
... A31: HZ0146 | B31: Hugo Lima | C31: Elegível | D31: 2500 | E31: 2800 | F31: -300 | G31: 2
